Workbook

Sheet Combined_Data
A1: review_id | B1: order_id | C1: product_id_review | D1: customer_id_review | E1: rating | F1: review_length | G1: verified_purchase | H1: review_date | I1: product_id_order | J1: seller_id | K1: customer_id_order | L1: order_date | M1: delivery_days | N1: discount_pct | O1: return_flag | P1: order_value | Q1: product_id_final | R1: product_id | S1: product_name | T1: category | U1: brand | V1: price | W1: seller_name | X1: region | Y1: joined_date | Z1: tenure_years | AA1: complaint_category | AB1: support_ticket_count
A2: R00001 | B2: O01484 | C2: P0097 | D2: C0340 | E2: 3 | F2: 86 | G2: No | H2: 45942 | I2: P0097 | J2: S021 | K2: C0340 | L2: 45926 | M2: 9 | N2: 30 | O2: 0 | P2: 389.2 | Q2: P0097 | R2: P0097 | S2: Fashion Item 27 | T2: Fashion | U2: Loomi | V2: 556 | W2: Seller_21 | X2: East | Y2: 43032 | Z2: 8.2
A3: R00002 | B3: O02186 | C3: P0099 | D3: C0049 | E3: 2 | F3: 98 | G3: Yes | H3: 45694 | I3: P0099 | J3: S005 | K3: C0049 | L3: 45683 | M3: 6 | N3: 15 | O3: 0 | P3: 791.35 | Q3: P0099 | R3: P0099 | S3: Fashion Item 29 | T3: Fashion | U3: Loomi | V3: 931 | W3: Seller_5 | X3: North | Y3: 44112 | Z3: 5.2 | AA3: Seller Behaviour | AB3: 1
A4: R00003 | B4: O02521 | C4: P0108 | D4: C0518 | E4: 4 | F4: 68 | G4: Yes | H4: 45994 | I4: P0108 | J4: S032 | K4: C0518 | L4: 45973 | M4: 8 | N4: 15 | O4: 0 | P4: 1983.05 | Q4: P0108 | R4: P0108 | S4: Beauty Item 3 | T4: Beauty | U4: Velvet | V4: 2333 | W4: Seller_32 | X4: West | Y4: 44128 | Z4: 5.2
A5: R00004 | B5: O03722 | C5: P0110 | D5: C0502 | E5: 2 | F5: 89 | G5: Yes | H5: 45689 | I5: P0110 | J5: S036 | K5: C0502 | L5: 45676 | M5: 12 | N5: 5 | O5: 0 | P5: 751.45 | Q5: P0110 | R5: P0110 | S5: Beauty Item 5 | T5: Beauty | U5: GlowLab | V5: 791 | W5: Seller_36 | X5: West | Y5: 44275 | Z5: 4.8 | AA5: Damaged Product | AB5: 1
A6: R00005 | B6: O03728 | C6: P0013 | D6: C1899 | E6: 3 | F6: 132 | G6: No | H6: 45847 | I6: P0013 | J6: S018 | K6: C1899 | L6: 45835 | M6: 5 | N6: 30 | O6: 0 | P6: 8999.9 | Q6: P0013 | R6: P0013 | S6: Electronics Item 13 | T6: Electronics | U6: PixelOne | V6: 12857 | W6: Seller_18 | X6: East | Y6: 44193 | Z6: 5
A7: R00006 | B7: O04525 | C7: P0086 | D7: C1646 | E7: 2 | F7: 89 | G7: No | H7: 45858 | I7: P0086 | J7: S032 | K7: C1646 | L7: 45842 | M7: 10 | N7: 20 | O7: 1 | P7: 272.8 | Q7: P0086 | R7: P0086 | S7: Fashion Item 16 | T7: Fashion | U7: StyleHub | V7: 341 | W7: Seller_32 | X7: West | Y7: 44128 | Z7: 5.2 | AA7: Late Delivery | AB7: 1
A8: R00007 | B8: O00235 | C8: P0173 | D8: C1951 | E8: 3 | F8: 54 | G8: Yes | H8: 45714 | I8: P0173 | J8: S005 | K8: C1951 | L8: 45706 | M8: 6 | N8: 5 | O8: 0 | P8: 2418.7 | Q8: P0173 | R8: P0173 | S8: Sports Item 33 | T8: Sports | U8: Pulse | V8: 2546 | W8: Seller_5 | X8: North | Y8: 44112 | Z8: 5.2
A9: R00008 | B9: O04736 | C9: P0022 | D9: C0675 | E9: 4 | F9: 79 | G9: Yes | H9: 45700 | I9: P0022 | J9: S030 | K9: C0675 | L9: 45683 | M9: 6 | N9: 10 | O9: 0 | P9: 4088.7 | Q9: P0022 | R9: P0022 | S9: Electronics Item 22 | T9: Electronics | U9: Zentra | V9: 4543 | W9: Seller_30 | X9: north | Y9: 45629 | Z9: 1.1
A10: R00009 | B10: O05840 | C10: P0062 | D10: C0430 | E10: 4 | F10: 69 | G10: No | H10: 45923 | I10: P0062 | J10: S028 | K10: C0430 | L10: 45904 | M10: 8 | N10: 10 | O10: 0 | P10: 1400.4 | Q10: P0062 | R10: P0062 | S10: Home Item 27 | T10: Home & Kitchen | U10: HomeNest | V10: 1556 | W10: Seller_28 | X10: east | Y10: 44203 | Z10: 5
A11: R00010 | B11: O02940 | C11: P0135 | D11: C1866 | E11: 4 | F11: 34 | G11: Yes | H11: 45866 | I11: P0135 | J11: S027 | K11: C1866 | L11: 45857 | M11: 8 | N11: 10 | O11: 0 | P11: 604.8 | Q11: P0135 | R11: P0135 | S11: Beauty Item 30 | T11: Beauty | U11: PureSkin | V11: 672 | W11: Seller_27 | X11: West | Y11: 43824 | Z11: 6
A12: R00011 | B12: O03054 | C12: P0064 | D12: C0986 | E12: 4 | F12: 27 | G12: Yes | H12: 45906 | I12: P0064 | J12: S007 | K12: C0986 | L12: 45896 | M12: 2 | N12: 5 | O12: 0 | P12: 2914.6 | Q12: P0064 | R12: P0064 | S12: Home Item 29 | T12: Home & Kitchen | U12: CookPro | V12: 3068 | W12: Seller_7 | X12: South | Y12: 44230 | Z12: 4.9
A13: R00012 | B13: O00868 | C13: P0184 | D13: C1550 | E13: 5 | F13: 78 | G13: No | H13: 45836 | I13: P0184 | J13: S038 | K13: C1550 | L13: 45824 | M13: 5 | N13: 20 | O13: 0 | P13: 203.2 | Q13: P0184 | R13: P0184 | S13: Books Item 9 | T13: Books & Stationery | U13: Scribe | V13: 254 | W13: Seller_38 | X13: Central | Y13: 44254 | Z13: 4.8
A14: R00013 | B14: O00277 | C14: P0195 | D14: C1922 | E14: 5 | F14: 39 | G14: Yes | H14: 45774 | I14: P0195 | J14: S001 | K14: C1922 | L14: 45767 | M14: 6 | N14: 0 | O14: 0 | P14: 1203 | Q14: P0195 | R14: P0195 | S14: Books Item 20 | T14: Books & Stationery | U14: PageTurn | V14: 1203 | W14: Seller_1 | X14: West | Y14: 43159 | Z14: 7.8
A15: R00014 | B15: O05799 | C15: P0050 | D15: C0548 | E15: 4 | F15: 103 | G15: No | H15: 45725 | I15: P0050 | J15: S026 | K15: C0548 | L15: 45717 | M15: 4 | N15: 20 | O15: 1 | P15: 297.6 | Q15: P0050 | R15: P0050 | S15: Home Item 15 | T15: Home & Kitchen | U15: CleanWave | V15: 372 | W15: Seller_26 | X15: East | Y15: 45173 | Z15: 2.3 | AA15: Other | AB15: 1
A16: R00015 | B16: O03513 | C16: P0029 | D16: C0551 | E16: 4 | F16: 42 | G16: Yes | H16: 45793 | I16: P0029 | J16: S006 | K16: C0551 | L16: 45783 | M16: 4 | N16: 15 | O16: 0 | P16: 3689 | Q16: P0029 | R16: P0029 | S16: Electronics Item 29 | T16: Electronics | U16: Zentra | V16: 4340 | W16: Seller_6 | X16: West | Y16: 43812 | Z16: 6.1
A17: R00016 | B17: O05790 | C17: P0092 | D17: C0199 | E17: 3 | F17: 48 | G17: Yes | H17: 45799 | I17: P0092 | J17: S036 | K17: C0199 | L17: 45781 | M17: 10 | N17: 0 | O17: 0 | P17: 1060 | Q17: P0092 | R17: P0092 | S17: Fashion Item 22 | T17: Fashion | U17: UrbanThread | V17: 1060 | W17: Seller_36 | X17: West | Y17: 44275 | Z17: 4.8
A18: R00017 | B18: O03199 | C18: P0088 | D18: C1310 | E18: 2 | F18: 48 | G18: Yes | H18: 45820 | I18: P0088 | J18: S027 | K18: C1310 | L18: 45809 | M18: 4 | N18: 10 | O18: 1 | P18: 3595.5 | Q18: P0088 | R18: P0088 | S18: Fashion Item 18 | T18: Fashion | U18: Loomi | V18: 3995 | W18: Seller_27 | X18: West | Y18: 43824 | Z18: 6 | AA18: Poor Quality | AB18: 1
A19: R00018 | B19: O05909 | C19: P0070 | D19: C1837 | E19: 4 | F19: 56 | G19: Yes | H19: 46031 | I19: P0070 | J19: S030 | K19: C1837 | L19: 46022 | M19: 2 | N19: 0 | O19: 0 | P19: 5306 | Q19: P0070 | R19: P0070 | S19: Home Item 35 | T19: Home & Kitchen | U19: CookPro | V19: 5306 | W19: Seller_30 | X19: north | Y19: 45629 | Z19: 1.1
A20: R00019 | B20: O05719 | C20: P0142 | D20: C0803 | E20: 4 | F20: 42 | G20: No | H20: 45753 | I20: P0142 | J20: S012 | K20: C0803 | L20: 45737 | M20: 5 | N20: 0 | O20: 0 | P20: 745 | Q20: P0142 | R20: P0142 | S20: Sports Item 2 | T20: Sports | U20: TrailMax | V20: 745 | W20: Seller_12 | X20: Central | Y20: 45507 | Z20: 1.4
A21: R00020 | B21: O02688 | C21: P0112 | D21: C0230 | E21: 2 | F21: 87 | G21: Yes | H21: 45926 | I21: P0112 | J21: S006 | K21: C0230 | L21: 45921 | M21: 2 | N21: 30 | O21: 0 | P21: 1182.3 | Q21: P0112 | R21: P0112 | S21: Beauty Item 7 | T21: Beauty | U21: PureSkin | V21: 1689 | W21: Seller_6 | X21: West | Y21: 43812 | Z21: 6.1 | AA21: Refund Delay | AB21: 1
A22: R00021 | B22: O00251 | C22: P0149 | D22: C0163 | E22: 5 | F22: 66 | G22: No | H22: 45971 | I22: P0149 | J22: S022 | K22: C0163 | L22: 45968 | M22: 2 | N22: 40 | O22: 0 | P22: 4703.4 | Q22: P0149 | R22: P0149 | S22: Sports Item 9 | T22: Sports | U22: TrailMax | V22: 7839 | W22: Seller_22 | X22: West | Y22: 43613 | Z22: 6.6
A23: R00022 | B23: O05462 | C23: P0041 | D23: C2397 | E23: 5 | F23: 23 | G23: Yes | H23: 45972 | I23: P0041 | J23: S013 | K23: C2397 | L23: 45956 | M23: 4 | N23: 30 | O23: 0 | P23: 1193.5 | Q23: P0041 | R23: P0041 | S23: Home Item 6 | T23: Home & Kitchen | U23: CookPro | V23: 1705 | W23: Seller_13 | X23: Central | Y23: 43138 | Z23: 7.9
A24: R00023 | B24: O03053 | C24: P0118 | D24: C1687 | E24: 4 | F24: 70 | G24: No | H24: 45974 | I24: P0118 | J24: S027 | K24: C1687 | L24: 45967 | M24: 3 | N24: 5 | O24: 0 | P24: 524.4 | Q24: P0118 | R24: P0118 | S24: Beauty Item 13 | T24: Beauty | U24: GlowLab | V24: 552 | W24: Seller_27 | X24: West | Y24: 43824 | Z24: 6
A25: R00024 | B25: O02712 | C25: P0135 | D25: C2143 | E25: 4 | F25: 79 | G25: Yes | H25: 45786 | I25: P0135 | J25: S008 | K25: C2143 | L25: 45772 | M25: 6 | N25: 5 | O25: 0 | P25: 638.4 | Q25: P0135 | R25: P0135 | S25: Beauty Item 30 | T25: Beauty | U25: PureSkin | V25: 672 | W25: Seller_8 | X25: South | Y25: 45659 | Z25: 1
A26: R00025 | B26: O03772 | C26: P0089 | D26: C1182 | E26: 4 | F26: 45 | G26: Yes | H26: 45696 | I26: P0089 | J26: S039 | K26: C1182 | L26: 45691 | M26: 4 | N26: 5 | O26: 0 | P26: 671.65 | Q26: P0089 | R26: P0089 | S26: Fashion Item 19 | T26: Fashion | U26: Vastra | V26: 707 | W26: Seller_39 | X26: Central | Y26: 44532 | Z26: 4.1
A27: R00026 | B27: O05989 | C27: P0030 | D27: C2444 | E27: 4 | F27: 35 | G27: Yes | H27: 45865 | I27: P0030 | J27: S016 | K27: C2444 | L27: 45846 | M27: 5 | N27: 0 | O27: 0 | P27: 25435 | Q27: P0030 | R27: P0030 | S27: Electronics Item 30 | T27: Electronics | U27: Zentra | V27: 25435 | W27: Seller_16 | X27: South | Y27: 43596 | Z27: 6.6
A28: R00027 | B28: O05646 | C28: P0003 | D28: C2483 | E28: 4 | F28: 76 | G28: Yes | H28: 45801 | I28: P0003 | J28: S028 | K28: C2483 | L28: 45783 | M28: 8 | N28: 5 | O28: 0 | P28: 1962.7 | Q28: P0003 | R28: P0003 | S28: Electronics Item 3 | T28: Electronics | U28: Sonix | V28: 2066 | W28: Seller_28 | X28: east | Y28: 44203 | Z28: 5
A29: R00028 | B29: O04618 | C29: P0171 | D29: C0860 | E29: 4 | F29: 56 | G29: Yes | H29: 45857 | I29: P0171 | J29: S031 | K29: C0860 | L29: 45841 | M29: 2 | N29: 5 | O29: 0 | P29: 4829.8 | Q29: P0171 | R29: P0171 | S29: Sports Item 31 | T29: Sports | U29: Pulse | V29: 5084 | W29: Seller_31 | X29: North | Y29: 44403 | Z29: 4.4
A30: R00029 | B30: O00369 | C30: P0081 | D30: C0035 | E30: 3 | F30: 64 | G30: No | H30: 45898 | I30: P0081 | J30: S007 | K30: C0035 | L30: 45880 | M30: 4 | N30: 30 | O30: 0 | P30: 1225.7 | Q30: P0081 | R30: P0081 | S30: Fashion Item 11 | T30: Fashion | U30: UrbanThread | V30: 1751 | W30: Seller_7 | X30: South | Y30: 44230 | Z30: 4.9
A31: R00030 | B31: O04917 | C31: P0087 | D31: C1832 | E31: 3 | F31: 169 | G31: No | H31: 45930 | I31: P0087 | J31: S039 | K31: C1832 | L31: 45920 | M31: 6 | N31: 20 | O31: 0 | P31: 333.6 | Q31: P0087 | R31: P0087 | S31: Fashion Item 17 | T31: Fashion | V31: 417 | W31: Seller_39 | X31: Central | Y31: 44532 | Z31: 4.1
A32: R00031 | B32: O01730 | C32: P0210 | D32: C0128 | E32: 5 | F32: 93 | G32: Yes | H32: 46001 | I32: P0210 | J32: S012 | K32: C0128 | L32: 45991 | M32: 4 | N32: 15 | O32: 0 | P32: 198.9 | Q32: P0210 | R32: P0210 | S32: Books Item 35 | T32: Books & Stationery | U32: PageTurn | V32: 234 | W32: Seller_12 | X32: Central | Y32: 45507 | Z32: 1.4
A33: R00032 | B33: O03876 | C33: P0174 | D33: C0201 | E33: 3 | F33: 52 | G33: Yes | H33: 45826 | I33: P0174 | J33: S010 | K33: C0201 | L33: 45808 | M33: 5 | N33: 5 | O33: 1 | P33: 599.45 | Q33: P0174 | R33: P0174 | S33: Sports Item 34 | T33: Sports | U33: FitCore | V33: 631 | W33: Seller_10 | X33: West | Y33: 43207 | Z33: 7.7 | AA33: Poor Quality | AB33: 1
A34: R00033 | B34: O00126 | C34: P0097 | D34: C1810 | E34: 2 | F34: 61 | G34: Yes | H34: 45738 | I34: P0097 | J34: S037 | K34: C1810 | L34: 45723 | M34: 7 | N34: 30 | O34: 0 | P34: 389.2 | Q34: P0097 | R34: P0097 | S34: Fashion Item 27 | T34: Fashion | U34: Loomi | V34: 556 | W34: Seller_37 | X34: East | Y34: 45880 | Z34: 0.4 | AA34: Other | AB34: 1
A35: R00034 | B35: O01989 | C35: P0082 | D35: C1248 | E35: 2 | F35: 116 | G35: No | H35: 46013 | I35: P0082 | J35: S006 | K35: C1248 | L35: 45998 | M35: 4 | N35: 0 | O35: 1 | P35: 322 | Q35: P0082 | R35: P0082 | S35: Fashion Item 12 | T35: Fashion | U35: Loomi | V35: 322 | W35: Seller_6 | X35: West | Y35: 43812 | Z35: 6.1 | AA35: damaged product | AB35: 1
A36: R00035 | B36: O00985 | C36: P0162 | D36: C1760 | E36: 5 | F36: 28 | G36: Yes | H36: 45873 | I36: P0162 | J36: S004 | K36: C1760 | L36: 45864 | M36: 2 | N36: 40 | O36: 0 | P36: 495 | Q36: P0162 | R36: P0162 | S36: Sports Item 22 | T36: Sports | U36: Pulse | V36: 825 | W36: Seller_4 | X36: South | Y36: 45629 | Z36: 1.1 | AA36: Other | AB36: 1
A37: R00036 | B37: O03954 | C37: P0069 | D37: C1372 | E37: 4 | F37: 55 | G37: Yes | H37: 45829 | I37: P0069 | J37: S040 | K37: C1372 | L37: 45816 | M37: 6 | N37: 15 | O37: 0 | P37: 9103.5 | Q37: P0069 | R37: P0069 | S37: Home Item 34 | T37: Home & Kitchen | U37: CookPro | V37: 10710 | W37: Seller_40 | X37: North | Y37: 44560 | Z37: 4
A38: R00037 | B38: O00932 | C38: P0156 | D38: C0544 | E38: 3 | F38: 89 | G38: Yes | H38: 45727 | I38: P0156 | J38: S019 | K38: C0544 | L38: 45713 | M38: 8 | N38: 10 | O38: 0 | P38: 2303.1 | Q38: P0156 | R38: P0156 | S38: Sports Item 16 | T38: Sports | U38: ActiveX | V38: 2559 | W38: Seller_19 | X38: Central | Y38: 44620 | Z38: 3.8
A39: R00038 | B39: O02032 | C39: P0175 | D39: C1913 | E39: 3 | F39: 63 | G39: No | H39: 45860 | I39: P0175 | J39: S015 | K39: C1913 | L39: 45842 | M39: 6 | N39: 20 | O39: 0 | P39: 840.8 | Q39: P0175 | R39: P0175 | S39: Sports Item 35 | T39: Sports | U39: FitCore | V39: 1051 | W39: Seller_15 | X39: West | Y39: 45415 | Z39: 1.7
A40: R00039 | B40: O00180 | C40: P0008 | D40: C2436 | E40: 3 | F40: 61 | G40: Yes | H40: 45953 | I40: P0008 | J40: S028 | K40: C2436 | L40: 45931 | M40: 15 | N40: 0 | O40: 0 | P40: 35078 | Q40: P0008 | R40: P0008 | S40: Electronics Item 8 | T40: Electronics | U40: VoltEdge | V40: 35078 | W40: Seller_28 | X40: east | Y40: 44203 | Z40: 5
...

Sheet Backup_Data
A1: review_id | B1: order_id | C1: product_id_review | D1: customer_id_review | E1: rating | F1: review_length | G1: verified_purchase | H1: review_date | I1: product_id_order | J1: seller_id | K1: customer_id_order | L1: order_date | M1: delivery_days | N1: discount_pct | O1: return_flag | P1: order_value | Q1: product_id_final | R1: product_id | S1: product_name | T1: category | U1: brand | V1: price | W1: seller_name | X1: region | Y1: joined_date | Z1: tenure_years | AA1: complaint_category | AB1: support_ticket_count
A2: R00001 | B2: O01484 | C2: P0097 | D2: C0340 | E2: 3 | F2: 86 | G2: No | H2: 45942 | I2: P0097 | J2: S021 | K2: C0340 | L2: 45926 | M2: 9 | N2: 30 | O2: 0 | P2: 389.2 | Q2: P0097 | R2: P0097 | S2: Fashion Item 27 | T2: Fashion | U2: Loomi | V2: 556 | W2: Seller_21 | X2: East | Y2: 43032 | Z2: 8.2
A3: R00002 | B3: O02186 | C3: P0099 | D3: C0049 | E3: 2 | F3: 98 | G3: Yes | H3: 45694 | I3: P0099 | J3: S005 | K3: C0049 | L3: 45683 | M3: 6 | N3: 15 | O3: 0 | P3: 791.35 | Q3: P0099 | R3: P0099 | S3: Fashion Item 29 | T3: Fashion | U3: Loomi | V3: 931 | W3: Seller_5 | X3: North | Y3: 44112 | Z3: 5.2 | AA3: Seller Behaviour | AB3: 1
A4: R00003 | B4: O02521 | C4: P0108 | D4: C0518 | E4: 4 | F4: 68 | G4: Yes | H4: 45994 | I4: P0108 | J4: S032 | K4: C0518 | L4: 45973 | M4: 8 | N4: 15 | O4: 0 | P4: 1983.05 | Q4: P0108 | R4: P0108 | S4: Beauty Item 3 | T4: Beauty | U4: Velvet | V4: 2333 | W4: Seller_32 | X4: West | Y4: 44128 | Z4: 5.2
A5: R00004 | B5: O03722 | C5: P0110 | D5: C0502 | E5: 2 | F5: 89 | G5: Yes | H5: 45689 | I5: P0110 | J5: S036 | K5: C0502 | L5: 45676 | M5: 12 | N5: 5 | O5: 0 | P5: 751.45 | Q5: P0110 | R5: P0110 | S5: Beauty Item 5 | T5: Beauty | U5: GlowLab | V5: 791 | W5: Seller_36 | X5: West | Y5: 44275 | Z5: 4.8 | AA5: Damaged Product | AB5: 1
A6: R00005 | B6: O03728 | C6: P0013 | D6: C1899 | E6: 3 | F6: 132 | G6: No | H6: 45847 | I6: P0013 | J6: S018 | K6: C1899 | L6: 45835 | M6: 5 | N6: 30 | O6: 0 | P6: 8999.9 | Q6: P0013 | R6: P0013 | S6: Electronics Item 13 | T6: Electronics | U6: PixelOne | V6: 12857 | W6: Seller_18 | X6: East | Y6: 44193 | Z6: 5
A7: R00006 | B7: O04525 | C7: P0086 | D7: C1646 | E7: 2 | F7: 89 | G7: No | H7: 45858 | I7: P0086 | J7: S032 | K7: C1646 | L7: 45842 | M7: 10 | N7: 20 | O7: 1 | P7: 272.8 | Q7: P0086 | R7: P0086 | S7: Fashion Item 16 | T7: Fashion | U7: StyleHub | V7: 341 | W7: Seller_32 | X7: West | Y7: 44128 | Z7: 5.2 | AA7: Late Delivery | AB7: 1
A8: R00007 | B8: O00235 | C8: P0173 | D8: C1951 | E8: 3 | F8: 54 | G8: Yes | H8: 45714 | I8: P0173 | J8: S005 | K8: C1951 | L8: 45706 | M8: 6 | N8: 5 | O8: 0 | P8: 2418.7 | Q8: P0173 | R8: P0173 | S8: Sports Item 33 | T8: Sports | U8: Pulse | V8: 2546 | W8: Seller_5 | X8: North | Y8: 44112 | Z8: 5.2
A9: R00008 | B9: O04736 | C9: P0022 | D9: C0675 | E9: 4 | F9: 79 | G9: Yes | H9: 45700 | I9: P0022 | J9: S030 | K9: C0675 | L9: 45683 | M9: 6 | N9: 10 | O9: 0 | P9: 4088.7 | Q9: P0022 | R9: P0022 | S9: Electronics Item 22 | T9: Electronics | U9: Zentra | V9: 4543 | W9: Seller_30 | X9: north | Y9: 45629 | Z9: 1.1
A10: R00009 | B10: O05840 | C10: P0062 | D10: C0430 | E10: 4 | F10: 69 | G10: No | H10: 45923 | I10: P0062 | J10: S028 | K10: C0430 | L10: 45904 | M10: 8 | N10: 10 | O10: 0 | P10: 1400.4 | Q10: P0062 | R10: P0062 | S10: Home Item 27 | T10: Home & Kitchen | U10: HomeNest | V10: 1556 | W10: Seller_28 | X10: east | Y10: 44203 | Z10: 5
A11: R00010 | B11: O02940 | C11: P0135 | D11: C1866 | E11: 4 | F11: 34 | G11: Yes | H11: 45866 | I11: P0135 | J11: S027 | K11: C1866 | L11: 45857 | M11: 8 | N11: 10 | O11: 0 | P11: 604.8 | Q11: P0135 | R11: P0135 | S11: Beauty Item 30 | T11: Beauty | U11: PureSkin | V11: 672 | W11: Seller_27 | X11: West | Y11: 43824 | Z11: 6
A12: R00011 | B12: O03054 | C12: P0064 | D12: C0986 | E12: 4 | F12: 27 | G12: Yes | H12: 45906 | I12: P0064 | J12: S007 | K12: C0986 | L12: 45896 | M12: 2 | N12: 5 | O12: 0 | P12: 2914.6 | Q12: P0064 | R12: P0064 | S12: Home Item 29 | T12: Home & Kitchen | U12: CookPro | V12: 3068 | W12: Seller_7 | X12: South | Y12: 44230 | Z12: 4.9
A13: R00012 | B13: O00868 | C13: P0184 | D13: C1550 | E13: 5 | F13: 78 | G13: No | H13: 45836 | I13: P0184 | J13: S038 | K13: C1550 | L13: 45824 | M13: 5 | N13: 20 | O13: 0 | P13: 203.2 | Q13: P0184 | R13: P0184 | S13: Books Item 9 | T13: Books & Stationery | U13: Scribe | V13: 254 | W13: Seller_38 | X13: Central | Y13: 44254 | Z13: 4.8
A14: R00013 | B14: O00277 | C14: P0195 | D14: C1922 | E14: 5 | F14: 39 | G14: Yes | H14: 45774 | I14: P0195 | J14: S001 | K14: C1922 | L14: 45767 | M14: 6 | N14: 0 | O14: 0 | P14: 1203 | Q14: P0195 | R14: P0195 | S14: Books Item 20 | T14: Books & Stationery | U14: PageTurn | V14: 1203 | W14: Seller_1 | X14: West | Y14: 43159 | Z14: 7.8
A15: R00014 | B15: O05799 | C15: P0050 | D15: C0548 | E15: 4 | F15: 103 | G15: No | H15: 45725 | I15: P0050 | J15: S026 | K15: C0548 | L15: 45717 | M15: 4 | N15: 20 | O15: 1 | P15: 297.6 | Q15: P0050 | R15: P0050 | S15: Home Item 15 | T15: Home & Kitchen | U15: CleanWave | V15: 372 | W15: Seller_26 | X15: East | Y15: 45173 | Z15: 2.3 | AA15: Other | AB15: 1
A16: R00015 | B16: O03513 | C16: P0029 | D16: C0551 | E16: 4 | F16: 42 | G16: Yes | H16: 45793 | I16: P0029 | J16: S006 | K16: C0551 | L16: 45783 | M16: 4 | N16: 15 | O16: 0 | P16: 3689 | Q16: P0029 | R16: P0029 | S16: Electronics Item 29 | T16: Electronics | U16: Zentra | V16: 4340 | W16: Seller_6 | X16: West | Y16: 43812 | Z16: 6.1
A17: R00016 | B17: O05790 | C17: P0092 | D17: C0199 | E17: 3 | F17: 48 | G17: Yes | H17: 45799 | I17: P0092 | J17: S036 | K17: C0199 | L17: 45781 | M17: 10 | N17: 0 | O17: 0 | P17: 1060 | Q17: P0092 | R17: P0092 | S17: Fashion Item 22 | T17: Fashion | U17: UrbanThread | V17: 1060 | W17: Seller_36 | X17: West | Y17: 44275 | Z17: 4.8
A18: R00017 | B18: O03199 | C18: P0088 | D18: C1310 | E18: 2 | F18: 48 | G18: Yes | H18: 45820 | I18: P0088 | J18: S027 | K18: C1310 | L18: 45809 | M18: 4 | N18: 10 | O18: 1 | P18: 3595.5 | Q18: P0088 | R18: P0088 | S18: Fashion Item 18 | T18: Fashion | U18: Loomi | V18: 3995 | W18: Seller_27 | X18: West | Y18: 43824 | Z18: 6 | AA18: Poor Quality | AB18: 1
A19: R00018 | B19: O05909 | C19: P0070 | D19: C1837 | E19: 4 | F19: 56 | G19: Yes | H19: 46031 | I19: P0070 | J19: S030 | K19: C1837 | L19: 46022 | M19: 2 | N19: 0 | O19: 0 | P19: 5306 | Q19: P0070 | R19: P0070 | S19: Home Item 35 | T19: Home & Kitchen | U19: CookPro | V19: 5306 | W19: Seller_30 | X19: north | Y19: 45629 | Z19: 1.1
A20: R00019 | B20: O05719 | C20: P0142 | D20: C0803 | E20: 4 | F20: 42 | G20: No | H20: 45753 | I20: P0142 | J20: S012 | K20: C0803 | L20: 45737 | M20: 5 | N20: 0 | O20: 0 | P20: 745 | Q20: P0142 | R20: P0142 | S20: Sports Item 2 | T20: Sports | U20: TrailMax | V20: 745 | W20: Seller_12 | X20: Central | Y20: 45507 | Z20: 1.4
A21: R00020 | B21: O02688 | C21: P0112 | D21: C0230 | E21: 2 | F21: 87 | G21: Yes | H21: 45926 | I21: P0112 | J21: S006 | K21: C0230 | L21: 45921 | M21: 2 | N21: 30 | O21: 0 | P21: 1182.3 | Q21: P0112 | R21: P0112 | S21: Beauty Item 7 | T21: Beauty | U21: PureSkin | V21: 1689 | W21: Seller_6 | X21: West | Y21: 43812 | Z21: 6.1 | AA21: Refund Delay | AB21: 1
A22: R00021 | B22: O00251 | C22: P0149 | D22: C0163 | E22: 5 | F22: 66 | G22: No | H22: 45971 | I22: P0149 | J22: S022 | K22: C0163 | L22: 45968 | M22: 2 | N22: 40 | O22: 0 | P22: 4703.4 | Q22: P0149 | R22: P0149 | S22: Sports Item 9 | T22: Sports | U22: TrailMax | V22: 7839 | W22: Seller_22 | X22: West | Y22: 43613 | Z22: 6.6
A23: R00022 | B23: O05462 | C23: P0041 | D23: C2397 | E23: 5 | F23: 23 | G23: Yes | H23: 45972 | I23: P0041 | J23: S013 | K23: C2397 | L23: 45956 | M23: 4 | N23: 30 | O23: 0 | P23: 1193.5 | Q23: P0041 | R23: P0041 | S23: Home Item 6 | T23: Home & Kitchen | U23: CookPro | V23: 1705 | W23: Seller_13 | X23: Central | Y23: 43138 | Z23: 7.9
A24: R00023 | B24: O03053 | C24: P0118 | D24: C1687 | E24: 4 | F24: 70 | G24: No | H24: 45974 | I24: P0118 | J24: S027 | K24: C1687 | L24: 45967 | M24: 3 | N24: 5 | O24: 0 | P24: 524.4 | Q24: P0118 | R24: P0118 | S24: Beauty Item 13 | T24: Beauty | U24: GlowLab | V24: 552 | W24: Seller_27 | X24: West | Y24: 43824 | Z24: 6
A25: R00024 | B25: O02712 | C25: P0135 | D25: C2143 | E25: 4 | F25: 79 | G25: Yes | H25: 45786 | I25: P0135 | J25: S008 | K25: C2143 | L25: 45772 | M25: 6 | N25: 5 | O25: 0 | P25: 638.4 | Q25: P0135 | R25: P0135 | S25: Beauty Item 30 | T25: Beauty | U25: PureSkin | V25: 672 | W25: Seller_8 | X25: South | Y25: 45659 | Z25: 1
A26: R00025 | B26: O03772 | C26: P0089 | D26: C1182 | E26: 4 | F26: 45 | G26: Yes | H26: 45696 | I26: P0089 | J26: S039 | K26: C1182 | L26: 45691 | M26: 4 | N26: 5 | O26: 0 | P26: 671.65 | Q26: P0089 | R26: P0089 | S26: Fashion Item 19 | T26: Fashion | U26: Vastra | V26: 707 | W26: Seller_39 | X26: Central | Y26: 44532 | Z26: 4.1
A27: R00026 | B27: O05989 | C27: P0030 | D27: C2444 | E27: 4 | F27: 35 | G27: Yes | H27: 45865 | I27: P0030 | J27: S016 | K27: C2444 | L27: 45846 | M27: 5 | N27: 0 | O27: 0 | P27: 25435 | Q27: P0030 | R27: P0030 | S27: Electronics Item 30 | T27: Electronics | U27: Zentra | V27: 25435 | W27: Seller_16 | X27: South | Y27: 43596 | Z27: 6.6
A28: R00027 | B28: O05646 | C28: P0003 | D28: C2483 | E28: 4 | F28: 76 | G28: Yes | H28: 45801 | I28: P0003 | J28: S028 | K28: C2483 | L28: 45783 | M28: 8 | N28: 5 | O28: 0 | P28: 1962.7 | Q28: P0003 | R28: P0003 | S28: Electronics Item 3 | T28: Electronics | U28: Sonix | V28: 2066 | W28: Seller_28 | X28: east | Y28: 44203 | Z28: 5
A29: R00028 | B29: O04618 | C29: P0171 | D29: C0860 | E29: 4 | F29: 56 | G29: Yes | H29: 45857 | I29: P0171 | J29: S031 | K29: C0860 | L29: 45841 | M29: 2 | N29: 5 | O29: 0 | P29: 4829.8 | Q29: P0171 | R29: P0171 | S29: Sports Item 31 | T29: Sports | U29: Pulse | V29: 5084 | W29: Seller_31 | X29: North | Y29: 44403 | Z29: 4.4
A30: R00029 | B30: O00369 | C30: P0081 | D30: C0035 | E30: 3 | F30: 64 | G30: No | H30: 45898 | I30: P0081 | J30: S007 | K30: C0035 | L30: 45880 | M30: 4 | N30: 30 | O30: 0 | P30: 1225.7 | Q30: P0081 | R30: P0081 | S30: Fashion Item 11 | T30: Fashion | U30: UrbanThread | V30: 1751 | W30: Seller_7 | X30: South | Y30: 44230 | Z30: 4.9
A31: R00030 | B31: O04917 | C31: P0087 | D31: C1832 | E31: 3 | F31: 169 | G31: No | H31: 45930 | I31: P0087 | J31: S039 | K31: C1832 | L31: 45920 | M31: 6 | N31: 20 | O31: 0 | P31: 333.6 | Q31: P0087 | R31: P0087 | S31: Fashion Item 17 | T31: Fashion | V31: 417 | W31: Seller_39 | X31: Central | Y31: 44532 | Z31: 4.1
A32: R00031 | B32: O01730 | C32: P0210 | D32: C0128 | E32: 5 | F32: 93 | G32: Yes | H32: 46001 | I32: P0210 | J32: S012 | K32: C0128 | L32: 45991 | M32: 4 | N32: 15 | O32: 0 | P32: 198.9 | Q32: P0210 | R32: P0210 | S32: Books Item 35 | T32: Books & Stationery | U32: PageTurn | V32: 234 | W32: Seller_12 | X32: Central | Y32: 45507 | Z32: 1.4
A33: R00032 | B33: O03876 | C33: P0174 | D33: C0201 | E33: 3 | F33: 52 | G33: Yes | H33: 45826 | I33: P0174 | J33: S010 | K33: C0201 | L33: 45808 | M33: 5 | N33: 5 | O33: 1 | P33: 599.45 | Q33: P0174 | R33: P0174 | S33: Sports Item 34 | T33: Sports | U33: FitCore | V33: 631 | W33: Seller_10 | X33: West | Y33: 43207 | Z33: 7.7 | AA33: Poor Quality | AB33: 1
A34: R00033 | B34: O00126 | C34: P0097 | D34: C1810 | E34: 2 | F34: 61 | G34: Yes | H34: 45738 | I34: P0097 | J34: S037 | K34: C1810 | L34: 45723 | M34: 7 | N34: 30 | O34: 0 | P34: 389.2 | Q34: P0097 | R34: P0097 | S34: Fashion Item 27 | T34: Fashion | U34: Loomi | V34: 556 | W34: Seller_37 | X34: East | Y34: 45880 | Z34: 0.4 | AA34: Other | AB34: 1
A35: R00034 | B35: O01989 | C35: P0082 | D35: C1248 | E35: 2 | F35: 116 | G35: No | H35: 46013 | I35: P0082 | J35: S006 | K35: C1248 | L35: 45998 | M35: 4 | N35: 0 | O35: 1 | P35: 322 | Q35: P0082 | R35: P0082 | S35: Fashion Item 12 | T35: Fashion | U35: Loomi | V35: 322 | W35: Seller_6 | X35: West | Y35: 43812 | Z35: 6.1 | AA35: damaged product | AB35: 1
A36: R00035 | B36: O00985 | C36: P0162 | D36: C1760 | E36: 5 | F36: 28 | G36: Yes | H36: 45873 | I36: P0162 | J36: S004 | K36: C1760 | L36: 45864 | M36: 2 | N36: 40 | O36: 0 | P36: 495 | Q36: P0162 | R36: P0162 | S36: Sports Item 22 | T36: Sports | U36: Pulse | V36: 825 | W36: Seller_4 | X36: South | Y36: 45629 | Z36: 1.1 | AA36: Other | AB36: 1
A37: R00036 | B37: O03954 | C37: P0069 | D37: C1372 | E37: 4 | F37: 55 | G37: Yes | H37: 45829 | I37: P0069 | J37: S040 | K37: C1372 | L37: 45816 | M37: 6 | N37: 15 | O37: 0 | P37: 9103.5 | Q37: P0069 | R37: P0069 | S37: Home Item 34 | T37: Home & Kitchen | U37: CookPro | V37: 10710 | W37: Seller_40 | X37: North | Y37: 44560 | Z37: 4
A38: R00037 | B38: O00932 | C38: P0156 | D38: C0544 | E38: 3 | F38: 89 | G38: Yes | H38: 45727 | I38: P0156 | J38: S019 | K38: C0544 | L38: 45713 | M38: 8 | N38: 10 | O38: 0 | P38: 2303.1 | Q38: P0156 | R38: P0156 | S38: Sports Item 16 | T38: Sports | U38: ActiveX | V38: 2559 | W38: Seller_19 | X38: Central | Y38: 44620 | Z38: 3.8
A39: R00038 | B39: O02032 | C39: P0175 | D39: C1913 | E39: 3 | F39: 63 | G39: No | H39: 45860 | I39: P0175 | J39: S015 | K39: C1913 | L39: 45842 | M39: 6 | N39: 20 | O39: 0 | P39: 840.8 | Q39: P0175 | R39: P0175 | S39: Sports Item 35 | T39: Sports | U39: FitCore | V39: 1051 | W39: Seller_15 | X39: West | Y39: 45415 | Z39: 1.7
A40: R00039 | B40: O00180 | C40: P0008 | D40: C2436 | E40: 3 | F40: 61 | G40: Yes | H40: 45953 | I40: P0008 | J40: S028 | K40: C2436 | L40: 45931 | M40: 15 | N40: 0 | O40: 0 | P40: 35078 | Q40: P0008 | R40: P0008 | S40: Electronics Item 8 | T40: Electronics | U40: VoltEdge | V40: 35078 | W40: Seller_28 | X40: east | Y40: 44203 | Z40: 5
...

Sheet Analysis
A1: Product Review Analysis
A3: Metric | B3: Value | D3: Data Quality Check | E3: Count
A4: Total Reviews | B4: =COUNTA(ProductReviewData[review_id]) -> 4200 | D4: Missing Ratings | E4: =COUNTBLANK(ProductReviewData[rating]) -> 0
A5: Average Customer Rating | B5: =IFERROR(AVERAGE(ProductReviewData[rating]),0) -> 3.6480952 | D5: Missing Product Names | E5: =COUNTBLANK(ProductReviewData[product_name]) -> 0
A6: Highest Rating | B6: =IFERROR(MAX(ProductReviewData[rating]),0) -> 5 | D6: Missing Categories | E6: =COUNTBLANK(ProductReviewData[category]) -> 0
A7: Lowest Rating | B7: =IFERROR(MIN(ProductReviewData[rating]),0) -> 1 | D7: Missing Seller Names | E7: =COUNTBLANK(ProductReviewData[seller_name]) -> 0
A8: Low-Rated Reviews (1-2) | B8: =COUNTIF(ProductReviewData[rating],"<=2") -> 451 | D8: Missing Delivery Days | E8: =COUNTBLANK(ProductReviewData[delivery_days]) -> 0
A9: High-Rated Reviews (4-5) | B9: =COUNTIF(ProductReviewData[rating],">=4") -> 2477 | D9: Long Reviews (>500 chars) | E9: =COUNTIF(ProductReviewData[review_length],">500") -> 0
A10: Average Delivery Time (days) | B10: =IFERROR(AVERAGE(ProductReviewData[delivery_days]),0) -> 5.8454762 | D10: Unmatched Product IDs | E10: {=SUMPRODUCT(--(ProductReviewData[product_id_review]<>ProductReviewData[product_id_order]))} -> 0
A11: Total Support Tickets | B11: =SUM(ProductReviewData[support_ticket_count]) -> 666 | D11: Blank Support Ticket Counts | E11: =COUNTBLANK(ProductReviewData[support_ticket_count]) -> 3534
A12: Low-Rated Review % | B12: =IFERROR(B8/B4,0) -> 0.10738095
A15: Product Category | B15: Review Count | D15: Rating Group | E15: Review Count
A16: Fashion | B16: =COUNTIF(ProductReviewData[category],A16) -> 670 | D16: Low (1-2) | E16: =COUNTIF(ProductReviewData[rating],"<=2") -> 451
A17: Beauty | B17: =COUNTIF(ProductReviewData[category],A17) -> 700 | D17: Medium (3) | E17: =COUNTIF(ProductReviewData[rating],3) -> 1272
A18: Electronics | B18: =COUNTIF(ProductReviewData[category],A18) -> 741 | D18: High (4-5) | E18: =COUNTIF(ProductReviewData[rating],">=4") -> 2477
A19: Sports | B19: =COUNTIF(ProductReviewData[category],A19) -> 645
A20: Home & Kitchen | B20: =COUNTIF(ProductReviewData[category],A20) -> 741
A21: Books & Stationery | B21: =COUNTIF(ProductReviewData[category],A21) -> 703
A24: Notes
A25: Support ticket totals use available numeric values; blank support_ticket_count cells are not treated as zero in the quality check.
A26: Unusually long reviews are flagged using review_length > 500 characters; no such records were found in the cleaned data.

Sheet Pivot_Tables
A1: Average Rating by Product Category | E1: Review Count by Product Category | I1: Seller Performance | M1: Verified vs Non-Verified Reviews | S1: Product Category | T1: Low (1-2) | U1: Medium (3) | V1: High (4-5)
A2: Product Category | B2: Average Rating | C2: Review Count | E2: Product Category | F2: Review Count | I2: Seller Name | J2: Average Rating | K2: Review Count | M2: Verified Purchase | N2: Average Rating | O2: Review Count | S2: Books & Stationery | T2: 0.046941679 | U2: 0.21906117 | V2: 0.73399716
A3: Books & Stationery | B3: 3.9687055 | C3: 703 | E3: Books & Stationery | F3: 703 | I3: Seller_35 | J3: 4.5049505 | K3: 101 | M3: No | N3: 3.3899177 | O3: 972 | S3: Sports | T3: 0.068217054 | U3: 0.28992248 | V3: 0.64186047
A4: Sports | B4: 3.7844961 | C4: 645 | E4: Sports | F4: 645 | I4: Seller_4 | J4: 4.1827957 | K4: 93 | M4: Yes | N4: 3.7258364 | O4: 3228 | S4: Home & Kitchen | T4: 0.10391363 | U4: 0.2928475 | V4: 0.60323887
A5: Home & Kitchen | B5: 3.6747638 | C5: 741 | E5: Home & Kitchen | F5: 741 | I5: Seller_9 | J5: 4.1067961 | K5: 103 | S5: Electronics | T5: 0.11066127 | U5: 0.31983806 | V5: 0.56950067
A6: Electronics | B6: 3.5951417 | C6: 741 | E6: Electronics | F6: 741 | I6: Seller_38 | J6: 4.1012658 | K6: 79 | S6: Beauty | T6: 0.13714286 | U6: 0.31428571 | V6: 0.54857143
A7: Beauty | B7: 3.5442857 | C7: 700 | E7: Beauty | F7: 700 | I7: Seller_31 | J7: 4.0720721 | K7: 111 | S7: Fashion | T7: 0.17761194 | U7: 0.38358209 | V7: 0.43880597
A8: Fashion | B8: 3.3179104 | C8: 670 | E8: Fashion | F8: 670 | I8: Seller_33 | J8: 4.0515464 | K8: 97
I9: Seller_25 | J9: 4.037037 | K9: 108
I10: Seller_29 | J10: 3.9904762 | K10: 105
I11: Seller_13 | J11: 3.9375 | K11: 112
I12: Seller_22 | J12: 3.9278351 | K12: 97
I13: Seller_32 | J13: 3.9072165 | K13: 97
I14: Seller_14 | J14: 3.8790323 | K14: 124
A15: Delivery Performance | E15: Customer Complaints | I15: Seller_11 | J15: 3.8571429 | K15: 98
A16: Delivery Days | B16: Average Rating | C16: Review Count | E16: Complaint Category | F16: Support Tickets | G16: Review Count | I16: Seller_16 | J16: 3.7777778 | K16: 90
A17: -1 | B17: 3.375 | C17: 8 | E17: Poor Quality | F17: 168 | G17: 168 | I17: Seller_2 | J17: 3.7647059 | K17: 102
A18: 1 | B18: 4 | C18: 14 | E18: Late Delivery | F18: 123 | G18: 123 | I18: Seller_34 | J18: 3.7589286 | K18: 112
A19: 2 | B19: 3.8387097 | C19: 217 | E19: Damaged Product | F19: 88 | G19: 88 | I19: Seller_7 | J19: 3.7522936 | K19: 109
A20: 3 | B20: 3.8463074 | C20: 501 | E20: Wrong Item | F20: 76 | G20: 76 | I20: Seller_30 | J20: 3.7416667 | K20: 120
A21: 4 | B21: 3.837535 | C21: 714 | E21: Refund Delay | F21: 61 | G21: 61 | I21: Seller_1 | J21: 3.71 | K21: 100
A22: 5 | B22: 3.7269231 | C22: 780 | E22: Other | F22: 46 | G22: 46 | I22: Seller_19 | J22: 3.6792453 | K22: 106
A23: 6 | B23: 3.681445 | C23: 609 | E23: Size/Fit Issue | F23: 40 | G23: 40 | I23: Seller_10 | J23: 3.67 | K23: 100
A24: 7 | B24: 3.6092437 | C24: 476 | E24: Seller Behaviour | F24: 37 | G24: 37 | I24: Seller_3 | J24: 3.6666667 | K24: 108
A25: 8 | B25: 3.4727273 | C25: 330 | E25: damaged product | F25: 8 | G25: 8 | I25: Seller_28 | J25: 3.6542056 | K25: 107
A26: 9 | B26: 3.1969697 | C26: 198 | E26: poor quality | F26: 4 | G26: 4 | I26: Seller_15 | J26: 3.6263736 | K26: 91
A27: 10 | B27: 3.1653543 | C27: 127 | E27: late delivery | F27: 4 | G27: 4 | I27: Seller_21 | J27: 3.6178862 | K27: 123
A28: 11 | B28: 3.1609195 | C28: 87 | E28: other | F28: 3 | G28: 3 | I28: Seller_17 | J28: 3.6034483 | K28: 116
... A32: 15 | B32: 2.8333333 | C32: 12 | E32: wrong item | F32: 2 | G32: 2 | I32: Seller_6 | J32: 3.4571429 | K32: 105
A33: 16 | B33: 4 | C33: 1 | I33: Seller_24 | J33: 3.4069767 | K33: 86
A34: 17 | B34: 2.5 | C34: 6 | I34: Seller_27 | J34: 3.3125 | K34: 112
A35: 18 | B35: 2.6666667 | C35: 3 | I35: Seller_12 | J35: 3.2542373 | K35: 118
A36: 20 | B36: 2 | C36: 1 | I36: Seller_26 | J36: 3.2242991 | K36: 107
A37: 90 | B37: 2.8 | C37: 5 | I37: Seller_18 | J37: 3.2213115 | K37: 122
I38: Seller_39 | J38: 3.2056075 | K38: 107
I39: Seller_23 | J39: 3.1709402 | K39: 117
I40: Seller_8 | J40: 3.0412371 | K40: 97
I41: Seller_5 | J41: 2.9230769 | K41: 104
I42: Seller_37 | J42: 2.78 | K42: 100
I45: Low-Rated Products (Average < 3)
...

Sheet Dashboard
A1: Product Review Dashboard | N1: Seller Name | O1: Review Count | P1: Average Rating | Q1: Bubble Size | S1: Delivery Days | T1: Rating
N2: Seller_14 | O2: 124 | P2: 3.8790323 | Q2: 124 | S2: 9 | T2: 3
A3: Total Reviews | B3: Average Rating | C3: Low-Rated Reviews | D3: High-Rated Reviews | E3: Avg Delivery Days | F3: Support Tickets | N3: Seller_21 | O3: 123 | P3: 3.6178862 | Q3: 123 | S3: 6 | T3: 2
A4: =Analysis!B4 -> 4200 | B4: =Analysis!B5 -> 3.6480952 | C4: =Analysis!B8 -> 451 | D4: =Analysis!B9 -> 2477 | E4: =Analysis!B10 -> 5.8454762 | F4: =Analysis!B11 -> 666 | N4: Seller_18 | O4: 122 | P4: 3.2213115 | Q4: 122 | S4: 8 | T4: 4
N5: Seller_30 | O5: 120 | P5: 3.7416667 | Q5: 120 | S5: 12 | T5: 2
N6: Seller_12 | O6: 118 | P6: 3.2542373 | Q6: 118 | S6: 5 | T6: 3
A7: Rating Group | B7: Review Count | D7: Product Category | E7: Average Rating | G7: Product Category | H7: Review Count | J7: Complaint Category | K7: Support Tickets | N7: Seller_40 | O7: 117 | P7: 3.5641026 | Q7: 117 | S7: 10 | T7: 2
A8: Low (1-2) | B8: 451 | D8: Books & Stationery | E8: 3.9687055 | G8: Books & Stationery | H8: 703 | J8: Poor Quality | K8: 172 | N8: Seller_23 | O8: 117 | P8: 3.1709402 | Q8: 117 | S8: 6 | T8: 3
A9: Medium (3) | B9: 1272 | D9: Sports | E9: 3.7844961 | G9: Sports | H9: 645 | J9: Late Delivery | K9: 127 | N9: Seller_17 | O9: 116 | P9: 3.6034483 | Q9: 116 | S9: 6 | T9: 4
A10: High (4-5) | B10: 2477 | D10: Home & Kitchen | E10: 3.6747638 | G10: Home & Kitchen | H10: 741 | J10: Damaged Product | K10: 96 | N10: Seller_36 | O10: 112 | P10: 3.4821429 | Q10: 112 | S10: 8 | T10: 4
D11: Electronics | E11: 3.5951417 | G11: Electronics | H11: 741 | J11: Wrong Item | K11: 78 | N11: Seller_27 | O11: 112 | P11: 3.3125 | Q11: 112 | S11: 8 | T11: 4
D12: Beauty | E12: 3.5442857 | G12: Beauty | H12: 700 | J12: Refund Delay | K12: 63 | N12: Seller_13 | O12: 112 | P12: 3.9375 | Q12: 112 | S12: 2 | T12: 4
D13: Fashion | E13: 3.3179104 | G13: Fashion | H13: 670 | J13: Other | K13: 49 | N13: Seller_34 | O13: 112 | P13: 3.7589286 | Q13: 112 | S13: 5 | T13: 5
J14: Size/Fit Issue | K14: 42 | N14: Seller_31 | O14: 111 | P14: 4.0720721 | Q14: 111 | S14: 6 | T14: 5
J15: Seller Behaviour | K15: 39 | N15: Seller_7 | O15: 109 | P15: 3.7522936 | Q15: 109 | S15: 4 | T15: 4
N16: Seller_25 | O16: 108 | P16: 4.037037 | Q16: 108 | S16: 4 | T16: 4
S17: 10 | T17: 3
S18: 4 | T18: 2
S19: 2 | T19: 4
S20: 5 | T20: 4
S21: 2 | T21: 2
S22: 2 | T22: 5
S23: 4 | T23: 5
S24: 3 | T24: 4
S25: 6 | T25: 4
S26: 4 | T26: 4
S27: 5 | T27: 4
S28: 8 | T28: 4
... S4201: 6 | T4201: 5

Sheet Key_Findings
A1: Key Findings and Recommendations
A2: Finding | B2: Value | C2: Interpretation
A3: Highest-rated category | B3: Books & Stationery | C3: Average rating 3.97.
A4: Lowest-rated category | B4: Fashion | C4: Average rating 3.32.
A5: Best seller by average rating | B5: Seller_35 | C5: Average rating 4.50.
A6: Worst seller by average rating | B6: Seller_37 | C6: Average rating 2.78.
A7: Verified vs non-verified | B7: 3.73 vs 3.39 | C7: Descriptive comparison only; not causal.
A8: Top complaint category | B8: Poor Quality | C8: 168 support tickets.
A9: Delivery vs rating | B9: See delivery summary | C9: Use the delivery table; no causal claim without statistical testing.
A10: Main satisfaction issue | B10: Low-rated reviews | C10: Focus on products and sellers with average ratings below 3.
A11: Recommendation 1 | B11: Prioritize low-rated products | C11: Investigate recurring defects or expectation gaps.
A12: Recommendation 2 | B12: Coach low-rated sellers | C12: Set seller-level improvement plans for weak average ratings.
A13: Recommendation 3 | B13: Reduce delivery delays | C13: Monitor longer delivery-day bands where ratings soften.
... A16: Recommendation 6 | B16: Review product descriptions | C16: Test whether product information matches customer expectations.
